Workbook
Name HistoryDate: History!$A:$A
Name HistorySecurity: History!$B:$B
Name HistoryPrice: History!$E:$E
Name HistoryQuantity: History!$D:$D
Name HistoryAction: History!$C:$C
Name HistoryTotal: History!$F:$F

Sheet Dashboard
B2: =Now() -> 46210.805 | I2: =if(OR((weekday(B2))=1,(weekday(B2))=7),"Market Closed",if(time(hour(now()),minute(now()),second(now()))>TIME(15,30,0),"Market Closed",if((time(hour(now()),minute(now()),second(now()))>TIME(9,15,0)),"Market Open","Market Closed"))) -> Market Closed
B3: INDEX
L4: EUROPE
B5: N.Y & N.DAQ | C5: N.Y & N.DAQ | D5: NASDAQ | E5: N.Y & N.DAQ | F5: NSE | G5: BSE | H5: TOKYO | I5: TAIWAN | J5: HONG KONG | K5: KOREA | L5: LONDON | M5: PARIS | N5: GERMANY | O5: EUROZONE
B6: Dow Jones | C6: S&500 | D6: Nasdaq | E6: Russell | F6: NIFTY 50 | G6: SENSEX | H6: Nikkei 225 | I6: TWSE | J6: HSI | K6: KOSPI | L6: FTSE 100 | M6: CAC 40 | N6: DAX | O6: STOXX 50
B7: .DJI | C7: .INX | D7: .IXIC | E7: RUT | F7: NIFTY_50 | G7: SENSEX | H7: NI225 | I7: IX0001 | J7: INDEXHANGSENG:HSI | K7: KOSPI | L7: UKX | M7: PX1 | N7: INDEXDB:DAX | O7: SX5E
B8: =IFERROR(__xludf.DUMMYFUNCTION("GOOGLEFINANCE(B7)"),53179.02) -> 53179.02 | C8: =IFERROR(__xludf.DUMMYFUNCTION("GOOGLEFINANCE(C7)"),7525.82) -> 7525.82 | D8: =IFERROR(__xludf.DUMMYFUNCTION("GOOGLEFINANCE(D7)"),25928.17) -> 25928.17 | E8: =IFERROR(__xludf.DUMMYFUNCTION("GOOGLEFINANCE(E7)"),3009.54) -> 3009.54 | F8: =IFERROR(__xludf.DUMMYFUNCTION("GOOGLEFINANCE(F7)"),24398.7) -> 24398.7 | G8: =IFERROR(__xludf.DUMMYFUNCTION("GOOGLEFINANCE(G7)"),78180.72) -> 78180.72 | H8: =IFERROR(__xludf.DUMMYFUNCTION("GOOGLEFINANCE(H7)"),68256.96) -> 68256.96 | I8: =IFERROR(__xludf.DUMMYFUNCTION("GOOGLEFINANCE(I7)"),45479.11) -> 45479.11 | J8: =IFERROR(__xludf.DUMMYFUNCTION("GOOGLEFINANCE(J7)"),23496.89) -> 23496.89 | K8: =IFERROR(__xludf.DUMMYFUNCTION("GOOGLEFINANCE(K7)"),7656.31) -> 7656.31 | L8: =IFERROR(__xludf.DUMMYFUNCTION("GOOGLEFINANCE(L7)"),10729.99) -> 10729.99 | M8: =IFERROR(__xludf.DUMMYFUNCTION("GOOGLEFINANCE(M7)"),8500.94) -> 8500.94 | N8: =IFERROR(__xludf.DUMMYFUNCTION("GOOGLEFINANCE(N7)"),25644.75) -> 25644.75 | O8: =IFERROR(__xludf.DUMMYFUNCTION("GOOGLEFINANCE(O7)"),6361.62) -> 6361.62
B9: =IFERROR(__xludf.DUMMYFUNCTION("GOOGLEFINANCE(B7,""Change"")"),123.11) -> 123.11 | C9: =IFERROR(__xludf.DUMMYFUNCTION("GOOGLEFINANCE(C7,""Change"")"),-11.61) -> -11.61 | D9: =IFERROR(__xludf.DUMMYFUNCTION("GOOGLEFINANCE(D7,""Change"")"),-192.99) -> -192.99 | E9: =IFERROR(__xludf.DUMMYFUNCTION("GOOGLEFINANCE(E7,""Change"")"),13.43) -> 13.43 | F9: =IFERROR(__xludf.DUMMYFUNCTION("GOOGLEFINANCE(F7,""Change"")"),-31.65) -> -31.65 | G9: =IFERROR(__xludf.DUMMYFUNCTION("GOOGLEFINANCE(G7,""Change"")"),-104.35) -> -104.35 | H9: =IFERROR(__xludf.DUMMYFUNCTION("GOOGLEFINANCE(H7,""Change"")"),-1480.73) -> -1480.73 | I9: =IFERROR(__xludf.DUMMYFUNCTION("GOOGLEFINANCE(I7,""Change"")"),-1077.28) -> -1077.28 | J9: =IFERROR(__xludf.DUMMYFUNCTION("GOOGLEFINANCE(J7,""Change"")"),-119.43) -> -119.43 | K9: =IFERROR(__xludf.DUMMYFUNCTION("GOOGLEFINANCE(K7,""Change"")"),-395.02) -> -395.02 | L9: =IFERROR(__xludf.DUMMYFUNCTION("GOOGLEFINANCE(L7,""Change"")"),78.22) -> 78.22 | M9: =IFERROR(__xludf.DUMMYFUNCTION("GOOGLEFINANCE(M7,""Change"")"),21.07) -> 21.07 | N9: =IFERROR(__xludf.DUMMYFUNCTION("GOOGLEFINANCE(N7,""Change"")"),-173.14) -> -173.14 | O9: =IFERROR(__xludf.DUMMYFUNCTION("GOOGLEFINANCE(O7,""Change"")"),-36.39) -> -36.39
B10: =B9/B8 -> 0.0023150107 | C10: =C9/C8 -> -0.001542689 | D10: =D9/D8 -> -0.0074432557 | E10: =E9/E8 -> 0.004462476 | F10: =F9/F8 -> -0.0012972003 | G10: =G9/G8 -> -0.0013347281 | H10: =H9/H8 -> -0.021693465 | I10: =I9/I8 -> -0.023687359 | ... O10: =O9/O8 -> -0.0057202411
B11: =IFERROR(__xludf.DUMMYFUNCTION("SPARKLINE(INDEX(GOOGLEFINANCE(B7,""Price"",WORKDAY(TODAY(),-252),today()),,2))"),"") | C11: =IFERROR(__xludf.DUMMYFUNCTION("SPARKLINE(INDEX(GOOGLEFINANCE(C7,""Price"",WORKDAY(TODAY(),-252),today()),,2))"),"") | D11: =IFERROR(__xludf.DUMMYFUNCTION("SPARKLINE(INDEX(GOOGLEFINANCE(D7,""Price"",WORKDAY(TODAY(),-252),today()),,2))"),"") | E11: =IFERROR(__xludf.DUMMYFUNCTION("SPARKLINE(INDEX(GOOGLEFINANCE(E7,""Price"",WORKDAY(TODAY(),-252),today()),,2))"),"") | F11: =IFERROR(__xludf.DUMMYFUNCTION("SPARKLINE(INDEX(GOOGLEFINANCE(F7,""Price"",WORKDAY(TODAY(),-252),today()),,2))"),"") | G11: =IFERROR(__xludf.DUMMYFUNCTION("SPARKLINE(INDEX(GOOGLEFINANCE(G7,""Price"",WORKDAY(TODAY(),-252),today()),,2))"),"") | H11: =IFERROR(__xludf.DUMMYFUNCTION("SPARKLINE(INDEX(GOOGLEFINANCE(H7,""Price"",WORKDAY(TODAY(),-252),today()),,2))"),"") | I11: =IFERROR(__xludf.DUMMYFUNCTION("SPARKLINE(INDEX(GOOGLEFINANCE(I7,""Price"",WORKDAY(TODAY(),-252),today()),,2))"),"") | J11: =IFERROR(__xludf.DUMMYFUNCTION("SPARKLINE(INDEX(GOOGLEFINANCE(J7,""Price"",WORKDAY(TODAY(),-252),today()),,2))"),"") | K11: =IFERROR(__xludf.DUMMYFUNCTION("SPARKLINE(INDEX(GOOGLEFINANCE(K7,""Price"",WORKDAY(TODAY(),-252),today()),,2))"),"") | L11: =IFERROR(__xludf.DUMMYFUNCTION("SPARKLINE(INDEX(GOOGLEFINANCE(L7,""Price"",WORKDAY(TODAY(),-252),today()),,2))"),"") | M11: =IFERROR(__xludf.DUMMYFUNCTION("SPARKLINE(INDEX(GOOGLEFINANCE(M7,""Price"",WORKDAY(TODAY(),-252),today()),,2))"),"") | N11: =IFERROR(__xludf.DUMMYFUNCTION("SPARKLINE(INDEX(GOOGLEFINANCE(N7,""Price"",WORKDAY(TODAY(),-252),today()),,2))"),"") | O11: =IFERROR(__xludf.DUMMYFUNCTION("SPARKLINE(INDEX(GOOGLEFINANCE(O7,""Price"",WORKDAY(TODAY(),-252),today()),,2))"),"")
B15: Single Stock Analysis | D15: =IFERROR(__xludf.DUMMYFUNCTION("GOOGLEFINANCE(C16,""Name"")"),"Affle 3i Ltd") -> Affle 3i Ltd | J15: ADRS
B16: Stock Overview | C16: NSE:AFFLE | D16: 12 Month Trend Lines | J16: HDFC | K16: ICICI | L16: INFOSYS | M16: WIPRO | N16: DR.REDDY | O16: YATRA ONLINE
B17: Stock Price | C17: =IFERROR(__xludf.DUMMYFUNCTION("GOOGLEFINANCE(C16,""price"")"),1465.1) -> 1465.1 | D17: =IFERROR(__xludf.DUMMYFUNCTION("SPARKLINE(INDEX(GOOGLEFINANCE(C16,""Price"",WORKDAY(TODAY(),-252),today()),,2),{""CHARTTYPE"",""COLUMN""})"),"") | J17: HDB | K17: IBN | L17: INFY | M17: WIT | N17: RDY | O17: YTRA
B18: 52 % Change | C18: =if(isblank(C16),"",(C17-C20)/C20) -> -0.32974976 | J18: =IFERROR(__xludf.DUMMYFUNCTION("GOOGLEFINANCE(J17)"),27.29) -> 27.29 | K18: =IFERROR(__xludf.DUMMYFUNCTION("GOOGLEFINANCE(K17)"),29.89) -> 29.89 | L18: =IFERROR(__xludf.DUMMYFUNCTION("GOOGLEFINANCE(L17)"),11.36) -> 11.36 | M18: =IFERROR(__xludf.DUMMYFUNCTION("GOOGLEFINANCE(M17)"),1.89) -> 1.89 | N18: =IFERROR(__xludf.DUMMYFUNCTION("GOOGLEFINANCE(N17)"),14.55) -> 14.55 | O18: =IFERROR(__xludf.DUMMYFUNCTION("GOOGLEFINANCE(O17)"),0.91) -> 0.91
B19: Signal | C19: =if(C18<-10%,"Buy","Hold") -> Buy | J19: =IFERROR(__xludf.DUMMYFUNCTION("GOOGLEFINANCE(J17,""Change"")"),-0.11) -> -0.11 | K19: =IFERROR(__xludf.DUMMYFUNCTION("GOOGLEFINANCE(K17,""Change"")"),-0.19) -> -0.19 | L19: =IFERROR(__xludf.DUMMYFUNCTION("GOOGLEFINANCE(L17,""Change"")"),0.48) -> 0.48 | M19: =IFERROR(__xludf.DUMMYFUNCTION("GOOGLEFINANCE(M17,""Change"")"),0.04) -> 0.04 | N19: =IFERROR(__xludf.DUMMYFUNCTION("GOOGLEFINANCE(N17,""Change"")"),0.19) -> 0.19 | O19: =IFERROR(__xludf.DUMMYFUNCTION("GOOGLEFINANCE(O17,""Change"")"),0.03) -> 0.03
B20: 52 Week High | C20: =IFERROR(__xludf.DUMMYFUNCTION("GOOGLEFINANCE(C16,""HIGH52"")"),2185.9) -> 2185.9 | J20: =J19/J18 -> -0.0040307805 | K20: =K19/K18 -> -0.006356641 | L20: =L19/L18 -> 0.042253521 | M20: =M19/M18 -> 0.021164021 | N20: =N19/N18 -> 0.013058419 | O20: =O19/O18 -> 0.032967033
B21: 52 Week Low | C21: =IFERROR(__xludf.DUMMYFUNCTION("GOOGLEFINANCE(C16,""LOW52"")"),1251.3) -> 1251.3 | J21: =IFERROR(__xludf.DUMMYFUNCTION("SPARKLINE(INDEX(GOOGLEFINANCE(J17,""Price"",WORKDAY(TODAY(),-252),today()),,2))"),"") | K21: =IFERROR(__xludf.DUMMYFUNCTION("SPARKLINE(INDEX(GOOGLEFINANCE(K17,""Price"",WORKDAY(TODAY(),-252),today()),,2))"),"") | L21: =IFERROR(__xludf.DUMMYFUNCTION("SPARKLINE(INDEX(GOOGLEFINANCE(L17,""Price"",WORKDAY(TODAY(),-252),today()),,2))"),"") | M21: =IFERROR(__xludf.DUMMYFUNCTION("SPARKLINE(INDEX(GOOGLEFINANCE(M17,""Price"",WORKDAY(TODAY(),-252),today()),,2))"),"") | N21: =IFERROR(__xludf.DUMMYFUNCTION("SPARKLINE(INDEX(GOOGLEFINANCE(N17,""Price"",WORKDAY(TODAY(),-252),today()),,2))"),"") | O21: =IFERROR(__xludf.DUMMYFUNCTION("SPARKLINE(INDEX(GOOGLEFINANCE(O17,""Price"",WORKDAY(TODAY(),-252),today()),,2))"),"")
B22: Market Cap (BN) | C22: =IFERROR(__xludf.DUMMYFUNCTION("googlefinance(C16,""Marketcap"")/1000000000"),206.059572106) -> 206.05957
B23: EPS | C23: =IFERROR(__xludf.DUMMYFUNCTION("GOOGLEFINANCE(C16,""EPS"")"),32.38) -> 32.38 | D23: Days Gainer | G23: =offset(B29:B122,MATCH(MAX(I29:I122),I29:I122,0),0,1) -> #N/A | I23: =(Max(I29:I122)) -> #N/A
B24: PE | C24: =IFERROR(__xludf.DUMMYFUNCTION("GOOGLEFINANCE(C16,""PE"")"),45.25) -> 45.25 | D24: Days Losser | G24: =offset(B29:B122,MATCH(MIN(I29:I122),I29:I122,0),0,1) -> #N/A | I24: =(Min(I29:I122)) -> #N/A
B25: Watchlists
B26: Portfolio Holdings
B27: Note: Target are set upon Mega cap - 10 to 20, Large cap - 15 to 25, Mid cap - 20 to 30, Small cap - 25 to 35
B28: Ticker | C28: Company Name | D28: 10% TB | E28: 15% TB | F28: Mk Cap | G28: Price | H28: MTB S | I28: % Ch | J28: 52Wk H | K28: 52 Wk L | L28: TB % | M28: MTB | N28: Cap Bar | O28: Mk Cap (In 1 Cr)
B29: BOM:514183 | C29: =IFERROR(__xludf.DUMMYFUNCTION("if(ISBLANK(B29),"""",GOOGLEFINANCE(B29,""NAME""))"),"Black Rose Industries Ltd") -> Black Rose Industries Ltd | D29: =if(ISBLANK(B29),"",if(L29<-10%,"B","H")) -> B | E29: =if(ISBLANK(B29),"",if(L29<-15%,"B","H")) -> B | F29: =IF(ISBLANK(B29), "", IF(O29 > 600000, "Mega Cap", IF(O29 > 30000, "Large Cap", IF(O29 > 7500, "Mid Cap", "Small Cap")))) -> Small Cap | G29: =IFERROR(__xludf.DUMMYFUNCTION("if(ISBLANK(B29),"""",GOOGLEFINANCE(B29,""price""))"),113.4) -> 113.4 | H29: =if(ISBLANK(B29),"",if(ISBLANK(M29),"",if(M29=0,"Extra",if(G29<M29,"Buy","Hold")))) -> Hold | I29: =IFERROR(__xludf.DUMMYFUNCTION("if(ISBLANK(B29),"""",GOOGLEFINANCE(B29,""CHANGEPCT"")/100)"),0.024399999999999998) -> 0.0244 | J29: =IFERROR(__xludf.DUMMYFUNCTION("if(ISBLANK(B29),"""",GOOGLEFINANCE(B29,""HIGH52""))"),137.95) -> 137.95 | K29: =IFERROR(__xludf.DUMMYFUNCTION("if(ISBLANK(B29),"""",GOOGLEFINANCE(B29,""LOW52""))"),61.0) -> 61 | L29: =if(isblank(B29),"",(G29-J29)/J29) -> -0.17796303 | M29: =J29-(J29*0.45) -> 75.8725 | N29: =IF(ISBLANK(B29), "", IF(AND(O29 >= 0, O29 <= 7500), "||||", IF(AND(O29 > 7500, O29 <= 30000), "|||", IF(AND(O29 > 30000, O29 <= 600000), "||", IF(O29 > 600000, "|", ""))))) -> |||| | O29: =IFERROR(__xludf.DUMMYFUNCTION("if(ISBLANK(B29),"""",googlefinance(B29,""Marketcap"")/10000000)"),571.0470062) -> 571.04701
B30: BOM:541167 | C30: =IFERROR(__xludf.DUMMYFUNCTION("if(ISBLANK(B30),"""",GOOGLEFINANCE(B30,""NAME""))"),"Yasho Industries Ltd") -> Yasho Industries Ltd | D30: =if(ISBLANK(B30),"",if(L30<-10%,"B","H")) -> H | E30: =if(ISBLANK(B30),"",if(L30<-15%,"B","H")) -> H | F30: =IF(ISBLANK(B30), "", IF(O30 > 600000, "Mega Cap", IF(O30 > 30000, "Large Cap", IF(O30 > 7500, "Mid Cap", "Small Cap")))) -> Small Cap | G30: =IFERROR(__xludf.DUMMYFUNCTION("if(ISBLANK(B30),"""",GOOGLEFINANCE(B30,""price""))"),2887.0) -> 2887 | H30: =if(ISBLANK(B30),"",if(ISBLANK(M30),"",if(M30=0,"Extra",if(G30<M30,"Buy","Hold")))) -> Hold | I30: =IFERROR(__xludf.DUMMYFUNCTION("if(ISBLANK(B30),"""",GOOGLEFINANCE(B30,""CHANGEPCT"")/100)"),0.0060999999999999995) -> 0.0061 | J30: =IFERROR(__xludf.DUMMYFUNCTION("if(ISBLANK(B30),"""",GOOGLEFINANCE(B30,""HIGH52""))"),3176.3) -> 3176.3 | K30: =IFERROR(__xludf.DUMMYFUNCTION("if(ISBLANK(B30),"""",GOOGLEFINANCE(B30,""LOW52""))"),1151.0) -> 1151 | L30: =if(isblank(B30),"",(G30-J30)/J30) -> -0.091080817 | M30: =J30-(J30*0.35) -> 2064.595 | N30: =IF(ISBLANK(B30), "", IF(AND(O30 >= 0, O30 <= 7500), "||||", IF(AND(O30 > 7500, O30 <= 30000), "|||", IF(AND(O30 > 30000, O30 <= 600000), "||", IF(O30 > 600000, "|", ""))))) -> |||| | O30: =IFERROR(__xludf.DUMMYFUNCTION("if(ISBLANK(B30),"""",googlefinance(B30,""Marketcap"")/10000000)"),3477.7469218) -> 3477.7469
B31: NSE:AARTIIND | C31: =IFERROR(__xludf.DUMMYFUNCTION("if(ISBLANK(B31),"""",GOOGLEFINANCE(B31,""NAME""))"),"Aarti Industries Ltd") -> Aarti Industries Ltd | D31: =if(ISBLANK(B31),"",if(L31<-10%,"B","H")) -> H | E31: =if(ISBLANK(B31),"",if(L31<-15%,"B","H")) -> H | F31: =IF(ISBLANK(B31), "", IF(O31 > 600000, "Mega Cap", IF(O31 > 30000, "Large Cap", IF(O31 > 7500, "Mid Cap", "Small Cap")))) -> Mid Cap | G31: =IFERROR(__xludf.DUMMYFUNCTION("if(ISBLANK(B31),"""",GOOGLEFINANCE(B31,""price""))"),478.6) -> 478.6 | H31: =if(ISBLANK(B31),"",if(ISBLANK(M31),"",if(M31=0,"Extra",if(G31<M31,"Buy","Hold")))) -> Hold | I31: =IFERROR(__xludf.DUMMYFUNCTION("if(ISBLANK(B31),"""",GOOGLEFINANCE(B31,""CHANGEPCT"")/100)"),-0.0203) -> -0.0203 | J31: =IFERROR(__xludf.DUMMYFUNCTION("if(ISBLANK(B31),"""",GOOGLEFINANCE(B31,""HIGH52""))"),523.1) -> 523.1 | K31: =IFERROR(__xludf.DUMMYFUNCTION("if(ISBLANK(B31),"""",GOOGLEFINANCE(B31,""LOW52""))"),338.05) -> 338.05 | L31: =if(isblank(B31),"",(G31-J31)/J31) -> -0.085069776 | M31: =J31-(J31*0.55) -> 235.395 | N31: =IF(ISBLANK(B31), "", IF(AND(O31 >= 0, O31 <= 7500), "||||", IF(AND(O31 > 7500, O31 <= 30000), "|||", IF(AND(O31 > 30000, O31 <= 600000), "||", IF(O31 > 600000, "|", ""))))) -> ||| | O31: =IFERROR(__xludf.DUMMYFUNCTION("if(ISBLANK(B31),"""",googlefinance(B31,""Marketcap"")/10000000)"),17360.0952973) -> 17360.095
B32: NSE:AFFLE | C32: =IFERROR(__xludf.DUMMYFUNCTION("if(ISBLANK(B32),"""",GOOGLEFINANCE(B32,""NAME""))"),"Affle 3i Ltd") -> Affle 3i Ltd | D32: =if(ISBLANK(B32),"",if(L32<-10%,"B","H")) -> B | E32: =if(ISBLANK(B32),"",if(L32<-15%,"B","H")) -> B | F32: =IF(ISBLANK(B32), "", IF(O32 > 600000, "Mega Cap", IF(O32 > 30000, "Large Cap", IF(O32 > 7500, "Mid Cap", "Small Cap")))) -> Mid Cap | G32: =IFERROR(__xludf.DUMMYFUNCTION("if(ISBLANK(B32),"""",GOOGLEFINANCE(B32,""price""))"),1465.1) -> 1465.1 | H32: =if(ISBLANK(B32),"",if(ISBLANK(M32),"",if(M32=0,"Extra",if(G32<M32,"Buy","Hold")))) -> Buy | I32: =IFERROR(__xludf.DUMMYFUNCTION("if(ISBLANK(B32),"""",GOOGLEFINANCE(B32,""CHANGEPCT"")/100)"),0.012199999999999999) -> 0.0122 | J32: =IFERROR(__xludf.DUMMYFUNCTION("if(ISBLANK(B32),"""",GOOGLEFINANCE(B32,""HIGH52""))"),2185.9) -> 2185.9 | K32: =IFERROR(__xludf.DUMMYFUNCTION("if(ISBLANK(B32),"""",GOOGLEFINANCE(B32,""LOW52""))"),1251.3) -> 1251.3 | L32: =if(isblank(B32),"",(G32-J32)/J32) -> -0.32974976 | M32: =J32-(J32*0.27) -> 1595.707 | N32: =IF(ISBLANK(B32), "", IF(AND(O32 >= 0, O32 <= 7500), "||||", IF(AND(O32 > 7500, O32 <= 30000), "|||", IF(AND(O32 > 30000, O32 <= 600000), "||", IF(O32 > 600000, "|", ""))))) -> ||| | O32: =IFERROR(__xludf.DUMMYFUNCTION("if(ISBLANK(B32),"""",googlefinance(B32,""Marketcap"")/10000000)"),20605.9572106) -> 20605.957
B33: NSE:ALKYLAMINE | C33: =IFERROR(__xludf.DUMMYFUNCTION("if(ISBLANK(B33),"""",GOOGLEFINANCE(B33,""NAME""))"),"Alkyl Amines Chemicals Ltd") -> Alkyl Amines Chemicals Ltd | D33: =if(ISBLANK(B33),"",if(L33<-10%,"B","H")) -> B | E33: =if(ISBLANK(B33),"",if(L33<-15%,"B","H")) -> B | F33: =IF(ISBLANK(B33), "", IF(O33 > 600000, "Mega Cap", IF(O33 > 30000, "Large Cap", IF(O33 > 7500, "Mid Cap", "Small Cap")))) -> Mid Cap | G33: =IFERROR(__xludf.DUMMYFUNCTION("if(ISBLANK(B33),"""",GOOGLEFINANCE(B33,""price""))"),1802.0) -> 1802 | H33: =if(ISBLANK(B33),"",if(ISBLANK(M33),"",if(M33=0,"Extra",if(G33<M33,"Buy","Hold")))) -> Hold | I33: =IFERROR(__xludf.DUMMYFUNCTION("if(ISBLANK(B33),"""",GOOGLEFINANCE(B33,""CHANGEPCT"")/100)"),0.0018) -> 0.0018 | J33: =IFERROR(__xludf.DUMMYFUNCTION("if(ISBLANK(B33),"""",GOOGLEFINANCE(B33,""HIGH52""))"),2438.8) -> 2438.8 | K33: =IFERROR(__xludf.DUMMYFUNCTION("if(ISBLANK(B33),"""",GOOGLEFINANCE(B33,""LOW52""))"),1212.0) -> 1212 | L33: =if(isblank(B33),"",(G33-J33)/J33) -> -0.26111202 | M33: =J33-(J33*0.4) -> 1463.28 | N33: =IF(ISBLANK(B33), "", IF(AND(O33 >= 0, O33 <= 7500), "||||", IF(AND(O33 > 7500, O33 <= 30000), "|||", IF(AND(O33 > 30000, O33 <= 600000), "||", IF(O33 > 600000, "|", ""))))) -> ||| | O33: =IFERROR(__xludf.DUMMYFUNCTION("if(ISBLANK(B33),"""",googlefinance(B33,""Marketcap"")/10000000)"),9157.1022823) -> 9157.1023
B34: NSE:AMIORG | C34: =IFERROR(__xludf.DUMMYFUNCTION("if(ISBLANK(B34),"""",GOOGLEFINANCE(B34,""NAME""))"),"#N/A") -> #N/A | D34: =if(ISBLANK(B34),"",if(L34<-10%,"B","H")) -> #N/A | E34: =if(ISBLANK(B34),"",if(L34<-15%,"B","H")) -> #N/A | F34: =IF(ISBLANK(B34), "", IF(O34 > 600000, "Mega Cap", IF(O34 > 30000, "Large Cap", IF(O34 > 7500, "Mid Cap", "Small Cap")))) -> #N/A | G34: =IFERROR(__xludf.DUMMYFUNCTION("if(ISBLANK(B34),"""",GOOGLEFINANCE(B34,""price""))"),"#N/A") -> #N/A | H34: =if(ISBLANK(B34),"",if(ISBLANK(M34),"",if(M34=0,"Extra",if(G34<M34,"Buy","Hold")))) -> #N/A | I34: =IFERROR(__xludf.DUMMYFUNCTION("if(ISBLANK(B34),"""",GOOGLEFINANCE(B34,""CHANGEPCT"")/100)"),"#N/A") -> #N/A | J34: =IFERROR(__xludf.DUMMYFUNCTION("if(ISBLANK(B34),"""",GOOGLEFINANCE(B34,""HIGH52""))"),"#N/A") -> #N/A | K34: =IFERROR(__xludf.DUMMYFUNCTION("if(ISBLANK(B34),"""",GOOGLEFINANCE(B34,""LOW52""))"),"#N/A") -> #N/A | L34: =if(isblank(B34),"",(G34-J34)/J34) -> #N/A | M34: =J34-(J34*0.27) -> #N/A | N34: =IF(ISBLANK(B34), "", IF(AND(O34 >= 0, O34 <= 7500), "||||", IF(AND(O34 > 7500, O34 <= 30000), "|||", IF(AND(O34 > 30000, O34 <= 600000), "||", IF(O34 > 600000, "|", ""))))) -> #N/A | O34: =IFERROR(__xludf.DUMMYFUNCTION("if(ISBLANK(B34),"""",googlefinance(B34,""Marketcap"")/10000000)"),"#N/A") -> #N/A
B35: NSE:ASIANPAINT | C35: =IFERROR(__xludf.DUMMYFUNCTION("if(ISBLANK(B35),"""",GOOGLEFINANCE(B35,""NAME""))"),"Asian Paints Ltd") -> Asian Paints Ltd | D35: =if(ISBLANK(B35),"",if(L35<-10%,"B","H")) -> H | E35: =if(ISBLANK(B35),"",if(L35<-15%,"B","H")) -> H | F35: =IF(ISBLANK(B35), "", IF(O35 > 600000, "Mega Cap", IF(O35 > 30000, "Large Cap", IF(O35 > 7500, "Mid Cap", "Small Cap")))) -> Large Cap | G35: =IFERROR(__xludf.DUMMYFUNCTION("if(ISBLANK(B35),"""",GOOGLEFINANCE(B35,""price""))"),2730.2) -> 2730.2 | H35: =if(ISBLANK(B35),"",if(ISBLANK(M35),"",if(M35=0,"Extra",if(G35<M35,"Buy","Hold")))) -> Hold | I35: =IFERROR(__xludf.DUMMYFUNCTION("if(ISBLANK(B35),"""",GOOGLEFINANCE(B35,""CHANGEPCT"")/100)"),-0.009000000000000001) -> -0.009 | J35: =IFERROR(__xludf.DUMMYFUNCTION("if(ISBLANK(B35),"""",GOOGLEFINANCE(B35,""HIGH52""))"),2985.7) -> 2985.7 | K35: =IFERROR(__xludf.DUMMYFUNCTION("if(ISBLANK(B35),"""",GOOGLEFINANCE(B35,""LOW52""))"),2115.0) -> 2115 | L35: =if(isblank(B35),"",(G35-J35)/J35) -> -0.085574572 | M35: =J35-(J35*0.4) -> 1791.42 | N35: =IF(ISBLANK(B35), "", IF(AND(O35 >= 0, O35 <= 7500), "||||", IF(AND(O35 > 7500, O35 <= 30000), "|||", IF(AND(O35 > 30000, O35 <= 600000), "||", IF(O35 > 600000, "|", ""))))) -> || | O35: =IFERROR(__xludf.DUMMYFUNCTION("if(ISBLANK(B35),"""",googlefinance(B35,""Marketcap"")/10000000)"),262067.7477967) -> 262067.75
B36: NSE:ASTRAL | C36: =IFERROR(__xludf.DUMMYFUNCTION("if(ISBLANK(B36),"""",GOOGLEFINANCE(B36,""NAME""))"),"Astral Ltd") -> Astral Ltd | D36: =if(ISBLANK(B36),"",if(L36<-10%,"B","H")) -> B | E36: =if(ISBLANK(B36),"",if(L36<-15%,"B","H")) -> B | F36: =IF(ISBLANK(B36), "", IF(O36 > 600000, "Mega Cap", IF(O36 > 30000, "Large Cap", IF(O36 > 7500, "Mid Cap", "Small Cap")))) -> Large Cap | G36: =IFERROR(__xludf.DUMMYFUNCTION("if(ISBLANK(B36),"""",GOOGLEFINANCE(B36,""price""))"),1356.9) -> 1356.9 | H36: =if(ISBLANK(B36),"",if(ISBLANK(M36),"",if(M36=0,"Extra",if(G36<M36,"Buy","Hold")))) -> Hold | I36: =IFERROR(__xludf.DUMMYFUNCTION("if(ISBLANK(B36),"""",GOOGLEFINANCE(B36,""CHANGEPCT"")/100)"),-0.0231) -> -0.0231 | J36: =IFERROR(__xludf.DUMMYFUNCTION("if(ISBLANK(B36),"""",GOOGLEFINANCE(B36,""HIGH52""))"),1768.7) -> 1768.7 | K36: =IFERROR(__xludf.DUMMYFUNCTION("if(ISBLANK(B36),"""",GOOGLEFINANCE(B36,""LOW52""))"),1263.7) -> 1263.7 | L36: =if(isblank(B36),"",(G36-J36)/J36) -> -0.23282637 | M36: =J36-(J36*0.5) -> 884.35 | N36: =IF(ISBLANK(B36), "", IF(AND(O36 >= 0, O36 <= 7500), "||||", IF(AND(O36 > 7500, O36 <= 30000), "|||", IF(AND(O36 > 30000, O36 <= 600000), "||", IF(O36 > 600000, "|", ""))))) -> || | O36: =IFERROR(__xludf.DUMMYFUNCTION("if(ISBLANK(B36),"""",googlefinance(B36,""Marketcap"")/10000000)"),36451.0430988) -> 36451.043
B37: NSE:AUBANK | C37: =IFERROR(__xludf.DUMMYFUNCTION("if(ISBLANK(B37),"""",GOOGLEFINANCE(B37,""NAME""))"),"AU Small Finance Bank Ltd") -> AU Small Finance Bank Ltd | D37: =if(ISBLANK(B37),"",if(L37<-10%,"B","H")) -> H | E37: =if(ISBLANK(B37),"",if(L37<-15%,"B","H")) -> H | F37: =IF(ISBLANK(B37), "", IF(O37 > 600000, "Mega Cap", IF(O37 > 30000, "Large Cap", IF(O37 > 7500, "Mid Cap", "Small Cap")))) -> Large Cap | G37: =IFERROR(__xludf.DUMMYFUNCTION("if(ISBLANK(B37),"""",GOOGLEFINANCE(B37,""price""))"),1066.0) -> 1066 | H37: =if(ISBLANK(B37),"",if(ISBLANK(M37),"",if(M37=0,"Extra",if(G37<M37,"Buy","Hold")))) -> Hold | I37: =IFERROR(__xludf.DUMMYFUNCTION("if(ISBLANK(B37),"""",GOOGLEFINANCE(B37,""CHANGEPCT"")/100)"),0.0043) -> 0.0043 | J37: =IFERROR(__xludf.DUMMYFUNCTION("if(ISBLANK(B37),"""",GOOGLEFINANCE(B37,""HIGH52""))"),1079.55) -> 1079.55 | K37: =IFERROR(__xludf.DUMMYFUNCTION("if(ISBLANK(B37),"""",GOOGLEFINANCE(B37,""LOW52""))"),682.15) -> 682.15 | L37: =if(isblank(B37),"",(G37-J37)/J37) -> -0.012551526 | M37: =J37-(J37*0.35) -> 701.7075 | N37: =IF(ISBLANK(B37), "", IF(AND(O37 >= 0, O37 <= 7500), "||||", IF(AND(O37 > 7500, O37 <= 30000), "|||", IF(AND(O37 > 30000, O37 <= 600000), "||", IF(O37 > 600000, "|", ""))))) -> || | O37: =IFERROR(__xludf.DUMMYFUNCTION("if(ISBLANK(B37),"""",googlefinance(B37,""Marketcap"")/10000000)"),79446.9502445) -> 79446.95
B38: NSE:BAJFINANCE | C38: =IFERROR(__xludf.DUMMYFUNCTION("if(ISBLANK(B38),"""",GOOGLEFINANCE(B38,""NAME""))"),"Bajaj Finance Ltd") -> Bajaj Finance Ltd | D38: =if(ISBLANK(B38),"",if(L38<-10%,"B","H")) -> H | E38: =if(ISBLANK(B38),"",if(L38<-15%,"B","H")) -> H | F38: =IF(ISBLANK(B38), "", IF(O38 > 600000, "Mega Cap", IF(O38 > 30000, "Large Cap", IF(O38 > 7500, "Mid Cap", "Small Cap")))) -> Large Cap | G38: =IFERROR(__xludf.DUMMYFUNCTION("if(ISBLANK(B38),"""",GOOGLEFINANCE(B38,""price""))"),1039.4) -> 1039.4 | H38: =if(ISBLANK(B38),"",if(ISBLANK(M38),"",if(M38=0,"Extra",if(G38<M38,"Buy","Hold")))) -> Hold | I38: =IFERROR(__xludf.DUMMYFUNCTION("if(ISBLANK(B38),"""",GOOGLEFINANCE(B38,""CHANGEPCT"")/100)"),0.01) -> 0.01 | J38: =IFERROR(__xludf.DUMMYFUNCTION("if(ISBLANK(B38),"""",GOOGLEFINANCE(B38,""HIGH52""))"),1102.5) -> 1102.5 | K38: =IFERROR(__xludf.DUMMYFUNCTION("if(ISBLANK(B38),"""",GOOGLEFINANCE(B38,""LOW52""))"),787.9) -> 787.9 | L38: =if(isblank(B38),"",(G38-J38)/J38) -> -0.05723356 | M38: =J38-(J38*0.25) -> 826.875 | N38: =IF(ISBLANK(B38), "", IF(AND(O38 >= 0, O38 <= 7500), "||||", IF(AND(O38 > 7500, O38 <= 30000), "|||", IF(AND(O38 > 30000, O38 <= 600000), "||", IF(O38 > 600000, "|", ""))))) -> || | O38: =IFERROR(__xludf.DUMMYFUNCTION("if(ISBLANK(B38),"""",googlefinance(B38,""Marketcap"")/10000000)"),64744.715915) -> 64744.716
B39: NSE:BATAINDIA | C39: =IFERROR(__xludf.DUMMYFUNCTION("if(ISBLANK(B39),"""",GOOGLEFINANCE(B39,""NAME""))"),"Bata India Ltd") -> Bata India Ltd | D39: =if(ISBLANK(B39),"",if(L39<-10%,"B","H")) -> B | E39: =if(ISBLANK(B39),"",if(L39<-15%,"B","H")) -> B | F39: =IF(ISBLANK(B39), "", IF(O39 > 600000, "Mega Cap", IF(O39 > 30000, "Large Cap", IF(O39 > 7500, "Mid Cap", "Small Cap")))) -> Mid Cap | G39: =IFERROR(__xludf.DUMMYFUNCTION("if(ISBLANK(B39),"""",GOOGLEFINANCE(B39,""price""))"),684.0) -> 684 | H39: =if(ISBLANK(B39),"",if(ISBLANK(M39),"",if(M39=0,"Extra",if(G39<M39,"Buy","Hold")))) -> Buy | I39: =IFERROR(__xludf.DUMMYFUNCTION("if(ISBLANK(B39),"""",GOOGLEFINANCE(B39,""CHANGEPCT"")/100)"),-0.0074) -> -0.0074 | J39: =IFERROR(__xludf.DUMMYFUNCTION("if(ISBLANK(B39),"""",GOOGLEFINANCE(B39,""HIGH52""))"),1284.9) -> 1284.9 | K39: =IFERROR(__xludf.DUMMYFUNCTION("if(ISBLANK(B39),"""",GOOGLEFINANCE(B39,""LOW52""))"),605.0) -> 605 | L39: =if(isblank(B39),"",(G39-J39)/J39) -> -0.46766285 | M39: =J39-(J39*0.27) -> 937.977 | N39: =IF(ISBLANK(B39), "", IF(AND(O39 >= 0, O39 <= 7500), "||||", IF(AND(O39 > 7500, O39 <= 30000), "|||", IF(AND(O39 > 30000, O39 <= 600000), "||", IF(O39 > 600000, "|", ""))))) -> ||| | O39: =IFERROR(__xludf.DUMMYFUNCTION("if(ISBLANK(B39),"""",googlefinance(B39,""Marketcap"")/10000000)"),8779.2723946) -> 8779.2724
B40: NSE:BERGEPAINT | C40: =IFERROR(__xludf.DUMMYFUNCTION("if(ISBLANK(B40),"""",GOOGLEFINANCE(B40,""NAME""))"),"Berger Paints India Ltd") -> Berger Paints India Ltd | D40: =if(ISBLANK(B40),"",if(L40<-10%,"B","H")) -> B | E40: =if(ISBLANK(B40),"",if(L40<-15%,"B","H")) -> B | F40: =IF(ISBLANK(B40), "", IF(O40 > 600000, "Mega Cap", IF(O40 > 30000, "Large Cap", IF(O40 > 7500, "Mid Cap", "Small Cap")))) -> Large Cap | G40: =IFERROR(__xludf.DUMMYFUNCTION("if(ISBLANK(B40),"""",GOOGLEFINANCE(B40,""price""))"),509.9) -> 509.9 | H40: =if(ISBLANK(B40),"",if(ISBLANK(M40),"",if(M40=0,"Extra",if(G40<M40,"Buy","Hold")))) -> Hold | I40: =IFERROR(__xludf.DUMMYFUNCTION("if(ISBLANK(B40),"""",GOOGLEFINANCE(B40,""CHANGEPCT"")/100)"),-0.0229) -> -0.0229 | J40: =IFERROR(__xludf.DUMMYFUNCTION("if(ISBLANK(B40),"""",GOOGLEFINANCE(B40,""HIGH52""))"),600.0) -> 600 | K40: =IFERROR(__xludf.DUMMYFUNCTION("if(ISBLANK(B40),"""",GOOGLEFINANCE(B40,""LOW52""))"),391.1) -> 391.1 | L40: =if(isblank(B40),"",(G40-J40)/J40) -> -0.15016667 | M40: =J40-(J40*0.3) -> 420 | N40: =IF(ISBLANK(B40), "", IF(AND(O40 >= 0, O40 <= 7500), "||||", IF(AND(O40 > 7500, O40 <= 30000), "|||", IF(AND(O40 > 30000, O40 <= 600000), "||", IF(O40 > 600000, "|", ""))))) -> || | O40: =IFERROR(__xludf.DUMMYFUNCTION("if(ISBLANK(B40),"""",googlefinance(B40,""Marketcap"")/10000000)"),59337.4062917) -> 59337.406
B41: NSE:BSE | C41: =IFERROR(__xludf.DUMMYFUNCTION("if(ISBLANK(B41),"""",GOOGLEFINANCE(B41,""NAME""))"),"BSE Ltd") -> BSE Ltd | D41: =if(ISBLANK(B41),"",if(L41<-10%,"B","H")) -> B | E41: =if(ISBLANK(B41),"",if(L41<-15%,"B","H")) -> B | F41: =IF(ISBLANK(B41), "", IF(O41 > 600000, "Mega Cap", IF(O41 > 30000, "Large Cap", IF(O41 > 7500, "Mid Cap", "Small Cap")))) -> Large Cap | G41: =IFERROR(__xludf.DUMMYFUNCTION("if(ISBLANK(B41),"""",GOOGLEFINANCE(B41,""price""))"),3678.7) -> 3678.7 | H41: =if(ISBLANK(B41),"",if(ISBLANK(M41),"",if(M41=0,"Extra",if(G41<M41,"Buy","Hold")))) -> Hold | I41: =IFERROR(__xludf.DUMMYFUNCTION("if(ISBLANK(B41),"""",GOOGLEFINANCE(B41,""CHANGEPCT"")/100)"),-0.0326) -> -0.0326 | J41: =IFERROR(__xludf.DUMMYFUNCTION("if(ISBLANK(B41),"""",GOOGLEFINANCE(B41,""HIGH52""))"),4446.8) -> 4446.8 | K41: =IFERROR(__xludf.DUMMYFUNCTION("if(ISBLANK(B41),"""",GOOGLEFINANCE(B41,""LOW52""))"),2021.5) -> 2021.5 | L41: =if(isblank(B41),"",(G41-J41)/J41) -> -0.17273095 | M41: =J41-(J41*0.55) -> 2001.06 | N41: =IF(ISBLANK(B41), "", IF(AND(O41 >= 0, O41 <= 7500), "||||", IF(AND(O41 > 7500, O41 <= 30000), "|||", IF(AND(O41 > 30000, O41 <= 600000), "||", IF(O41 > 600000, "|", ""))))) -> || | O41: =IFERROR(__xludf.DUMMYFUNCTION("if(ISBLANK(B41),"""",googlefinance(B41,""Marketcap"")/10000000)"),149833.1179282) -> 149833.12
B42: NSE:CAMS | C42: =IFERROR(__xludf.DUMMYFUNCTION("if(ISBLANK(B42),"""",GOOGLEFINANCE(B42,""NAME""))"),"Computer Age Management Services Ltd") -> Computer Age Management Services Ltd | D42: =if(ISBLANK(B42),"",if(L42<-10%,"B","H")) -> H | E42: =if(ISBLANK(B42),"",if(L42<-15%,"B","H")) -> H | F42: =IF(ISBLANK(B42), "", IF(O42 > 600000, "Mega Cap", IF(O42 > 30000, "Large Cap", IF(O42 > 7500, "Mid Cap", "Small Cap")))) -> Mid Cap | G42: =IFERROR(__xludf.DUMMYFUNCTION("if(ISBLANK(B42),"""",GOOGLEFINANCE(B42,""price""))"),777.35) -> 777.35 | H42: =if(ISBLANK(B42),"",if(ISBLANK(M42),"",if(M42=0,"Extra",if(G42<M42,"Buy","Hold")))) -> Hold | I42: =IFERROR(__xludf.DUMMYFUNCTION("if(ISBLANK(B42),"""",GOOGLEFINANCE(B42,""CHANGEPCT"")/100)"),-0.014499999999999999) -> -0.0145 | J42: =IFERROR(__xludf.DUMMYFUNCTION("if(ISBLANK(B42),"""",GOOGLEFINANCE(B42,""HIGH52""))"),857.8) -> 857.8 | K42: =IFERROR(__xludf.DUMMYFUNCTION("if(ISBLANK(B42),"""",GOOGLEFINANCE(B42,""LOW52""))"),611.4) -> 611.4 | L42: =if(isblank(B42),"",(G42-J42)/J42) -> -0.09378643 | M42: =J42-(J42*0.45) -> 471.79 | N42: =IF(ISBLANK(B42), "", IF(AND(O42 >= 0, O42 <= 7500), "||||", IF(AND(O42 > 7500, O42 <= 30000), "|||", IF(AND(O42 > 30000, O42 <= 600000), "||", IF(O42 > 600000, "|", ""))))) -> ||| | O42: =IFERROR(__xludf.DUMMYFUNCTION("if(ISBLANK(B42),"""",googlefinance(B42,""Marketcap"")/10000000)"),19294.1917485) -> 19294.192
B43: NSE:CDSL | C43: =IFERROR(__xludf.DUMMYFUNCTION("if(ISBLANK(B43),"""",GOOGLEFINANCE(B43,""NAME""))"),"Central Depository Services (India) Ltd") -> Central Depository Services (India) Ltd | D43: =if(ISBLANK(B43),"",if(L43<-10%,"B","H")) -> B | E43: =if(ISBLANK(B43),"",if(L43<-15%,"B","H")) -> B | F43: =IF(ISBLANK(B43), "", IF(O43 > 600000, "Mega Cap", IF(O43 > 30000, "Large Cap", IF(O43 > 7500, "Mid Cap", "Small Cap")))) -> Mid Cap | G43: =IFERROR(__xludf.DUMMYFUNCTION("if(ISBLANK(B43),"""",GOOGLEFINANCE(B43,""price""))"),1358.0) -> 1358 | H43: =if(ISBLANK(B43),"",if(ISBLANK(M43),"",if(M43=0,"Extra",if(G43<M43,"Buy","Hold")))) -> Hold | I43: =IFERROR(__xludf.DUMMYFUNCTION("if(ISBLANK(B43),"""",GOOGLEFINANCE(B43,""CHANGEPCT"")/100)"),-4.0E-4) -> -0.0004 | J43: =IFERROR(__xludf.DUMMYFUNCTION("if(ISBLANK(B43),"""",GOOGLEFINANCE(B43,""HIGH52""))"),1794.9) -> 1794.9 | K43: =IFERROR(__xludf.DUMMYFUNCTION("if(ISBLANK(B43),"""",GOOGLEFINANCE(B43,""LOW52""))"),1116.3) -> 1116.3 | L43: =if(isblank(B43),"",(G43-J43)/J43) -> -0.24341189 | M43: =J43-(J43*0.55) -> 807.705 | N43: =IF(ISBLANK(B43), "", IF(AND(O43 >= 0, O43 <= 7500), "||||", IF(AND(O43 > 7500, O43 <= 30000), "|||", IF(AND(O43 > 30000, O43 <= 600000), "||", IF(O43 > 600000, "|", ""))))) -> ||| | O43: =IFERROR(__xludf.DUMMYFUNCTION("if(ISBLANK(B43),"""",googlefinance(B43,""Marketcap"")/10000000)"),28382.18642) -> 28382.186
B44: NSE:CGPOWER | C44: =IFERROR(__xludf.DUMMYFUNCTION("if(ISBLANK(B44),"""",GOOGLEFINANCE(B44,""NAME""))"),"CG Power and Industrial Solutions Ltd") -> CG Power and Industrial Solutions Ltd | D44: =if(ISBLANK(B44),"",if(L44<-10%,"B","H")) -> H | E44: =if(ISBLANK(B44),"",if(L44<-15%,"B","H")) -> H | F44: =IF(ISBLANK(B44), "", IF(O44 > 600000, "Mega Cap", IF(O44 > 30000, "Large Cap", IF(O44 > 7500, "Mid Cap", "Small Cap")))) -> Large Cap | G44: =IFERROR(__xludf.DUMMYFUNCTION("if(ISBLANK(B44),"""",GOOGLEFINANCE(B44,""price""))"),910.45) -> 910.45 | H44: =if(ISBLANK(B44),"",if(ISBLANK(M44),"",if(M44=0,"Extra",if(G44<M44,"Buy","Hold")))) -> Extra | I44: =IFERROR(__xludf.DUMMYFUNCTION("if(ISBLANK(B44),"""",GOOGLEFINANCE(B44,""CHANGEPCT"")/100)"),-0.0158) -> -0.0158 | J44: =IFERROR(__xludf.DUMMYFUNCTION("if(ISBLANK(B44),"""",GOOGLEFINANCE(B44,""HIGH52""))"),980.9) -> 980.9 | K44: =IFERROR(__xludf.DUMMYFUNCTION("if(ISBLANK(B44),"""",GOOGLEFINANCE(B44,""LOW52""))"),525.5) -> 525.5 | L44: =if(isblank(B44),"",(G44-J44)/J44) -> -0.071821796 | M44: 0 | N44: =IF(ISBLANK(B44), "", IF(AND(O44 >= 0, O44 <= 7500), "||||", IF(AND(O44 > 7500, O44 <= 30000), "|||", IF(AND(O44 > 30000, O44 <= 600000), "||", IF(O44 > 600000, "|", ""))))) -> || | O44: =IFERROR(__xludf.DUMMYFUNCTION("if(ISBLANK(B44),"""",googlefinance(B44,""Marketcap"")/10000000)"),139273.68) -> 139273.68
...

Sheet CHECK
A1: =Now() -> 46210.805 | H1: =if(OR((weekday(A1))=1,(weekday(A1))=7),"Market Closed",if(time(hour(now()),minute(now()),second(now()))>TIME(15,30,0),"Market Closed",if((time(hour(now()),minute(now()),second(now()))>TIME(9,15,0)),"Market Open","Market Closed"))) -> Market Closed
A2: BEFORE MARKET
A3: AMERICA | E3: ADRS | J3: ASIA
A4: N.Y & N.DAQ | B4: N.Y & N.DAQ | C4: NASDAQ | D4: N.Y & N.DAQ | J4: NSE | K4: BSE | L4: TOKYO | M4: TAIWAN | N4: HONG KONG | O4: KOREA
A5: Dow Jones | B5: S&500 | C5: Nasdaq | D5: Russell | E5: Infosys | F5: ICICI | G5: WIPRO | H5: HDFC | I5: Dr. Reddy | J5: NIFTY 50 | K5: SENSEX | L5: Nikkei 225 | M5: TWSE | N5: HSI | O5: KOSPI
A6: .DJI | B6: .INX | C6: .IXIC | D6: RUT | E6: INFY | F6: IBN | G6: WIT | H6: HDB | I6: RDY | J6: NIFTY_50 | K6: SENSEX | L6: NI225 | M6: IX0001 | N6: INDEXHANGSENG:HSI | O6: KOSPI
A7: =IFERROR(__xludf.DUMMYFUNCTION("GOOGLEFINANCE(A6)"),53179.02) -> 53179.02 | B7: =IFERROR(__xludf.DUMMYFUNCTION("GOOGLEFINANCE(B6)"),7525.82) -> 7525.82 | C7: =IFERROR(__xludf.DUMMYFUNCTION("GOOGLEFINANCE(C6)"),25928.17) -> 25928.17 | D7: =IFERROR(__xludf.DUMMYFUNCTION("GOOGLEFINANCE(D6)"),3009.54) -> 3009.54 | E7: =IFERROR(__xludf.DUMMYFUNCTION("GOOGLEFINANCE(E6)"),11.36) -> 11.36 | F7: =IFERROR(__xludf.DUMMYFUNCTION("GOOGLEFINANCE(F6)"),29.89) -> 29.89 | G7: =IFERROR(__xludf.DUMMYFUNCTION("GOOGLEFINANCE(G6)"),1.89) -> 1.89 | H7: =IFERROR(__xludf.DUMMYFUNCTION("GOOGLEFINANCE(H6)"),27.29) -> 27.29 | I7: =IFERROR(__xludf.DUMMYFUNCTION("GOOGLEFINANCE(I6)"),14.55) -> 14.55 | J7: =IFERROR(__xludf.DUMMYFUNCTION("GOOGLEFINANCE(J6)"),24398.7) -> 24398.7 | K7: =IFERROR(__xludf.DUMMYFUNCTION("GOOGLEFINANCE(K6)"),78180.72) -> 78180.72 | L7: =IFERROR(__xludf.DUMMYFUNCTION("GOOGLEFINANCE(L6)"),68256.96) -> 68256.96 | M7: =IFERROR(__xludf.DUMMYFUNCTION("GOOGLEFINANCE(M6)"),45479.11) -> 45479.11 | N7: =IFERROR(__xludf.DUMMYFUNCTION("GOOGLEFINANCE(N6)"),23496.89) -> 23496.89 | O7: =IFERROR(__xludf.DUMMYFUNCTION("GOOGLEFINANCE(O6)"),7656.31) -> 7656.31
A8: =IFERROR(__xludf.DUMMYFUNCTION("GOOGLEFINANCE(A6,""Change"")"),123.11) -> 123.11 | B8: =IFERROR(__xludf.DUMMYFUNCTION("GOOGLEFINANCE(B6,""Change"")"),-11.61) -> -11.61 | C8: =IFERROR(__xludf.DUMMYFUNCTION("GOOGLEFINANCE(C6,""Change"")"),-192.99) -> -192.99 | D8: =IFERROR(__xludf.DUMMYFUNCTION("GOOGLEFINANCE(D6,""Change"")"),13.43) -> 13.43 | E8: =IFERROR(__xludf.DUMMYFUNCTION("GOOGLEFINANCE(E6,""Change"")"),0.48) -> 0.48 | F8: =IFERROR(__xludf.DUMMYFUNCTION("GOOGLEFINANCE(F6,""Change"")"),-0.19) -> -0.19 | G8: =IFERROR(__xludf.DUMMYFUNCTION("GOOGLEFINANCE(G6,""Change"")"),0.04) -> 0.04 | H8: =IFERROR(__xludf.DUMMYFUNCTION("GOOGLEFINANCE(H6,""Change"")"),-0.11) -> -0.11 | I8: =IFERROR(__xludf.DUMMYFUNCTION("GOOGLEFINANCE(I6,""Change"")"),0.19) -> 0.19 | J8: =IFERROR(__xludf.DUMMYFUNCTION("GOOGLEFINANCE(J6,""Change"")"),-31.65) -> -31.65 | K8: =IFERROR(__xludf.DUMMYFUNCTION("GOOGLEFINANCE(K6,""Change"")"),-104.35) -> -104.35 | L8: =IFERROR(__xludf.DUMMYFUNCTION("GOOGLEFINANCE(L6,""Change"")"),-1480.73) -> -1480.73 | M8: =IFERROR(__xludf.DUMMYFUNCTION("GOOGLEFINANCE(M6,""Change"")"),-1077.28) -> -1077.28 | N8: =IFERROR(__xludf.DUMMYFUNCTION("GOOGLEFINANCE(N6,""Change"")"),-119.43) -> -119.43 | O8: =IFERROR(__xludf.DUMMYFUNCTION("GOOGLEFINANCE(O6,""Change"")"),-395.02) -> -395.02
A9: =A8/A7 -> 0.0023150107 | B9: =B8/B7 -> -0.001542689 | C9: =C8/C7 -> -0.0074432557 | D9: =D8/D7 -> 0.004462476 | E9: =E8/E7 -> 0.042253521 | F9: =F8/F7 -> -0.006356641 | G9: =G8/G7 -> 0.021164021 | H9: =H8/H7 -> -0.0040307805 | ... O9: =O8/O7 -> -0.051594045
A10: =IFERROR(__xludf.DUMMYFUNCTION("SPARKLINE(INDEX(GOOGLEFINANCE(A6,""Price"",WORKDAY(TODAY(),-252),today()),,2),{""CHARTTYPE"",""COLUMN""})"),"") | B10: =IFERROR(__xludf.DUMMYFUNCTION("SPARKLINE(INDEX(GOOGLEFINANCE(B6,""Price"",WORKDAY(TODAY(),-252),today()),,2),{""CHARTTYPE"",""COLUMN""})"),"") | C10: =IFERROR(__xludf.DUMMYFUNCTION("SPARKLINE(INDEX(GOOGLEFINANCE(C6,""Price"",WORKDAY(TODAY(),-252),today()),,2),{""CHARTTYPE"",""COLUMN""})"),"") | D10: =IFERROR(__xludf.DUMMYFUNCTION("SPARKLINE(INDEX(GOOGLEFINANCE(D6,""Price"",WORKDAY(TODAY(),-252),today()),,2),{""CHARTTYPE"",""COLUMN""})"),"") | E10: =IFERROR(__xludf.DUMMYFUNCTION("SPARKLINE(INDEX(GOOGLEFINANCE(E6,""Price"",WORKDAY(TODAY(),-252),today()),,2),{""CHARTTYPE"",""COLUMN""})"),"") | F10: =IFERROR(__xludf.DUMMYFUNCTION("SPARKLINE(INDEX(GOOGLEFINANCE(F6,""Price"",WORKDAY(TODAY(),-252),today()),,2),{""CHARTTYPE"",""COLUMN""})"),"") | G10: =IFERROR(__xludf.DUMMYFUNCTION("SPARKLINE(INDEX(GOOGLEFINANCE(G6,""Price"",WORKDAY(TODAY(),-252),today()),,2),{""CHARTTYPE"",""COLUMN""})"),"") | H10: =IFERROR(__xludf.DUMMYFUNCTION("SPARKLINE(INDEX(GOOGLEFINANCE(H6,""Price"",WORKDAY(TODAY(),-252),today()),,2),{""CHARTTYPE"",""COLUMN""})"),"") | I10: =IFERROR(__xludf.DUMMYFUNCTION("SPARKLINE(INDEX(GOOGLEFINANCE(I6,""Price"",WORKDAY(TODAY(),-252),today()),,2),{""CHARTTYPE"",""COLUMN""})"),"") | J10: =IFERROR(__xludf.DUMMYFUNCTION("SPARKLINE(INDEX(GOOGLEFINANCE(J6,""Price"",WORKDAY(TODAY(),-252),today()),,2),{""CHARTTYPE"",""COLUMN""})"),"") | K10: =IFERROR(__xludf.DUMMYFUNCTION("SPARKLINE(INDEX(GOOGLEFINANCE(K6,""Price"",WORKDAY(TODAY(),-252),today()),,2),{""CHARTTYPE"",""COLUMN""})"),"") | L10: =IFERROR(__xludf.DUMMYFUNCTION("SPARKLINE(INDEX(GOOGLEFINANCE(L6,""Price"",WORKDAY(TODAY(),-252),today()),,2),{""CHARTTYPE"",""COLUMN""})"),"") | M10: =IFERROR(__xludf.DUMMYFUNCTION("SPARKLINE(INDEX(GOOGLEFINANCE(M6,""Price"",WORKDAY(TODAY(),-252),today()),,2),{""CHARTTYPE"",""COLUMN""})"),"") | N10: =IFERROR(__xludf.DUMMYFUNCTION("SPARKLINE(INDEX(GOOGLEFINANCE(N6,""Price"",WORKDAY(TODAY(),-252),today()),,2),{""CHARTTYPE"",""COLUMN""})"),"") | O10: =IFERROR(__xludf.DUMMYFUNCTION("SPARKLINE(INDEX(GOOGLEFINANCE(O6,""Price"",WORKDAY(TODAY(),-252),today()),,2),{""CHARTTYPE"",""COLUMN""})"),"")
A15: DURING MARKET
A17: Major Stocks
A19: HDFC | B19: ICICI | C19: TCS | D19: Infosys | E19: RELIANCE
A20: HDFCBANK | B20: ICICIBANK | C20: NSE:TCS | D20: INFY | E20: NSE:RELIANCE
A21: =IFERROR(__xludf.DUMMYFUNCTION("GOOGLEFINANCE(A20)"),827.5) -> 827.5 | B21: =IFERROR(__xludf.DUMMYFUNCTION("GOOGLEFINANCE(B20)"),1412.0) -> 1412 | C21: =IFERROR(__xludf.DUMMYFUNCTION("GOOGLEFINANCE(C20)"),2095.9) -> 2095.9 | D21: =IFERROR(__xludf.DUMMYFUNCTION("GOOGLEFINANCE(D20)"),11.36) -> 11.36 | E21: =IFERROR(__xludf.DUMMYFUNCTION("GOOGLEFINANCE(E20)"),1305.0) -> 1305
A22: =IFERROR(__xludf.DUMMYFUNCTION("GOOGLEFINANCE(A20,""Change"")"),-2.35) -> -2.35 | B22: =IFERROR(__xludf.DUMMYFUNCTION("GOOGLEFINANCE(B20,""Change"")"),-14.9) -> -14.9 | C22: =IFERROR(__xludf.DUMMYFUNCTION("GOOGLEFINANCE(C20,""Change"")"),38.3) -> 38.3 | D22: =IFERROR(__xludf.DUMMYFUNCTION("GOOGLEFINANCE(D20,""Change"")"),0.48) -> 0.48 | E22: =IFERROR(__xludf.DUMMYFUNCTION("GOOGLEFINANCE(E20,""Change"")"),-16.3) -> -16.3
A23: =A22/A21 -> -0.0028398792 | B23: =B22/B21 -> -0.010552408 | C23: =C22/C21 -> 0.018273773 | D23: =D22/D21 -> 0.042253521 | E23: =E22/E21 -> -0.012490421
A24: =IFERROR(__xludf.DUMMYFUNCTION("SPARKLINE(INDEX(GOOGLEFINANCE(A20,""Price"",WORKDAY(TODAY(),-252),today()),,2),{""CHARTTYPE"",""COLUMN""})"),"") | B24: =IFERROR(__xludf.DUMMYFUNCTION("SPARKLINE(INDEX(GOOGLEFINANCE(B20,""Price"",WORKDAY(TODAY(),-252),today()),,2),{""CHARTTYPE"",""COLUMN""})"),"") | C24: =IFERROR(__xludf.DUMMYFUNCTION("SPARKLINE(INDEX(GOOGLEFINANCE(C20,""Price"",WORKDAY(TODAY(),-252),today()),,2),{""CHARTTYPE"",""COLUMN""})"),"") | D24: =IFERROR(__xludf.DUMMYFUNCTION("SPARKLINE(INDEX(GOOGLEFINANCE(D20,""Price"",WORKDAY(TODAY(),-252),today()),,2),{""CHARTTYPE"",""COLUMN""})"),"") | E24: =IFERROR(__xludf.DUMMYFUNCTION("SPARKLINE(INDEX(GOOGLEFINANCE(E20,""Price"",WORKDAY(TODAY(),-252),today()),,2),{""CHARTTYPE"",""COLUMN""})"),"")
A29: AFTER MARKET
A31: FII & DII DATA
A32: CRUDE OIL

Sheet Fresh Shares List
A1: =Now() -> 46210.805 | H1: =if(OR((weekday(A1))=1,(weekday(A1))=7),"Market Closed",if(time(hour(now()),minute(now()),second(now()))>TIME(15,30,0),"Market Closed",if((time(hour(now()),minute(now()),second(now()))>TIME(9,15,0)),"Market Open","Market Closed"))) -> Market Closed
A2: Single Stock Analysis | C2: No | D2: TB% | E2: Ticker | G2: Company Name | I2: =IFERROR(__xludf.DUMMYFUNCTION("GOOGLEFINANCE(B3,""Name"")"),"Hindustan Aeronautics Ltd") -> Hindustan Aeronautics Ltd
A3: Stock Overview | B3: NSE:HAL | C3: 1 | D3: =MIN(IFNA(K16:K47,"")) -> -0.70453208 | E3: {=XLOOKUP(D3,K16:K203,A16:A203)} -> BOM:530825 | G3: =IFERROR(__xludf.DUMMYFUNCTION("GOOGLEFINANCE(E3,""NAME"")"),"Daikaffil Chemicals India Ltd") -> Daikaffil Chemicals India Ltd | I3: 12 Month Trend Lines
A4: Stock Price | B4: =IFERROR(__xludf.DUMMYFUNCTION("GOOGLEFINANCE(B3,""price"")"),4401.0) -> 4401 | C4: 2 | D4: =SMALL(IFNA(K16:K47,""),2) -> -0.46011673 | E4: {=XLOOKUP(D4,K16:K204,A16:A204)} -> NSE:ROUTE | G4: =IFERROR(__xludf.DUMMYFUNCTION("GOOGLEFINANCE(E4,""NAME"")"),"Route Mobile Ltd") -> Route Mobile Ltd | I4: =IFERROR(__xludf.DUMMYFUNCTION("SPARKLINE(INDEX(GOOGLEFINANCE(B3,""Price"",WORKDAY(TODAY(),-252),today()),,2),{""CHARTTYPE"",""COLUMN""})"),"")
A5: 52 % Change | B5: =if(isblank(B3),"",(B4-B7)/B7) -> -0.13109576 | C5: 3 | D5: =SMALL(IFNA(K16:K48,""),3) -> -0.45711766 | E5: {=XLOOKUP(D5,K16:K205,A16:A205)} -> NSE:WHIRLPOOL | G5: =IFERROR(__xludf.DUMMYFUNCTION("GOOGLEFINANCE(E5,""NAME"")"),"Whirlpool Of India Ltd") -> Whirlpool Of India Ltd
A6: Signal | B6: =if(B5<-10%,"Buy","Hold") -> Buy | C6: 4 | D6: =SMALL(IFNA(K16:K49,""),4) -> -0.39267016 | E6: {=XLOOKUP(D6,K16:K206,A16:A206)} -> NSE:MHRIL | G6: =IFERROR(__xludf.DUMMYFUNCTION("GOOGLEFINANCE(E6,""NAME"")"),"Mahindra Holidays and Resorts India Ltd") -> Mahindra Holidays and Resorts India Ltd
A7: 52 Week High | B7: =IFERROR(__xludf.DUMMYFUNCTION("GOOGLEFINANCE(B3,""HIGH52"")"),5065.0) -> 5065 | C7: 5 | D7: =SMALL(IFNA(K16:K50,""),5) -> -0.37988281 | E7: {=XLOOKUP(D7,K16:K207,A16:A207)} -> NSE:WESTLIFE | G7: =IFERROR(__xludf.DUMMYFUNCTION("GOOGLEFINANCE(E7,""NAME"")"),"Westlife Foodworld Ltd") -> Westlife Foodworld Ltd
A8: 52 Week Low | B8: =IFERROR(__xludf.DUMMYFUNCTION("GOOGLEFINANCE(B3,""LOW52"")"),3479.1) -> 3479.1 | C8: Days Gainer | E8: =offset(A16:A49,MATCH(MAX(H16:H49),H16:H49,0),0,1) -> NSE:HAL | G8: =(Max(H16:H49)) -> 0.0115
A9: Market Cap (BN) | B9: =IFERROR(__xludf.DUMMYFUNCTION("googlefinance(B3,""Marketcap"")/1000000000"),2942.895888) -> 2942.8959
A10: EPS | B10: =IFERROR(__xludf.DUMMYFUNCTION("GOOGLEFINANCE(B3,""EPS"")"),136.3) -> 136.3 | C10: Days Losser | E10: =offset(A16:A49,MATCH(MIN(H16:H49),H16:H49,0),0,1) -> NSE:DIVISLAB | G10: =(Min(H16:H50)) -> -0.0342
A11: PE | B11: =IFERROR(__xludf.DUMMYFUNCTION("GOOGLEFINANCE(B3,""PE"")"),32.29) -> 32.29
A12: Watchlists
A13: Fresh Shares Check Four Reason*
A15: Ticker | B15: Company Name | C15: 10% TB | D15: 15% TB | E15: Mk Cap | F15: Price | G15: MTB S | H15: % Ch | I15: 52Wk H | J15: 52 Wk L | K15: TB % | L15: MTB | M15: Cap Bar | N15: Mk Cap (In 1 Cr)
A16: BOM:530825 | B16: =IFERROR(__xludf.DUMMYFUNCTION("if(ISBLANK(A16),"""",GOOGLEFINANCE(A16,""NAME""))"),"Daikaffil Chemicals India Ltd") -> Daikaffil Chemicals India Ltd | C16: =if(ISBLANK(A16),"",if(K16<-10%,"Buy","Hold")) -> Buy | D16: =if(ISBLANK(A16),"",if(K16<-15%,"Buy","Hold")) -> Buy | E16: =if(ISBLANK(A16),"",if(N16>1401,"Large cap",if(N16>100,"Mid cap","Small cap"))) -> Small cap | F16: =IFERROR(__xludf.DUMMYFUNCTION("if(ISBLANK(A16),"""",GOOGLEFINANCE(A16,""price""))"),50.2) -> 50.2 | G16: =if(ISBLANK(A16),"",if(L16=0,"Buy@CMP",if(F16<L16,"Buy","Hold"))) -> Buy@CMP | H16: =IFERROR(__xludf.DUMMYFUNCTION("if(ISBLANK(A16),"""",GOOGLEFINANCE(A16,""CHANGEPCT"")/100)"),-0.0199) -> -0.0199 | I16: =IFERROR(__xludf.DUMMYFUNCTION("if(ISBLANK(A16),"""",GOOGLEFINANCE(A16,""HIGH52""))"),169.9) -> 169.9 | J16: =IFERROR(__xludf.DUMMYFUNCTION("if(ISBLANK(A16),"""",GOOGLEFINANCE(A16,""LOW52""))"),28.48) -> 28.48 | K16: =if(isblank(A16),"",(F16-I16)/I16) -> -0.70453208 | L16: 0 | M16: =IF(ISBLANK(A16), "", IF(AND($N16 >= 0, $N16 <= 75), "||||", IF(AND($N16 > 75, $N16 <= 300), "|||", IF(AND($N16 > 300, $N16 <= 6000), "||", IF($N16 > 6000, "|", ""))))) -> |||| | N16: =IFERROR(__xludf.DUMMYFUNCTION("if(ISBLANK(A16),"""",googlefinance(A16,""Marketcap"")/1000000000)"),0.301200004) -> 0.3012
A17: BOM:539837 | B17: =IFERROR(__xludf.DUMMYFUNCTION("if(ISBLANK(A17),"""",GOOGLEFINANCE(A17,""NAME""))"),"Raghav Productivity Enhancers Ltd") -> Raghav Productivity Enhancers Ltd | C17: =if(ISBLANK(A17),"",if(K17<-10%,"Buy","Hold")) -> Hold | D17: =if(ISBLANK(A17),"",if(K17<-15%,"Buy","Hold")) -> Hold | E17: =if(ISBLANK(A17),"",if(N17>1401,"Large cap",if(N17>100,"Mid cap","Small cap"))) -> Small cap | F17: =IFERROR(__xludf.DUMMYFUNCTION("if(ISBLANK(A17),"""",GOOGLEFINANCE(A17,""price""))"),1306.0) -> 1306 | G17: =if(ISBLANK(A17),"",if(L17=0,"Buy@CMP",if(F17<L17,"Buy","Hold"))) -> Buy@CMP | H17: =IFERROR(__xludf.DUMMYFUNCTION("if(ISBLANK(A17),"""",GOOGLEFINANCE(A17,""CHANGEPCT"")/100)"),0.0087) -> 0.0087 | I17: =IFERROR(__xludf.DUMMYFUNCTION("if(ISBLANK(A17),"""",GOOGLEFINANCE(A17,""HIGH52""))"),1319.75) -> 1319.75 | J17: =IFERROR(__xludf.DUMMYFUNCTION("if(ISBLANK(A17),"""",GOOGLEFINANCE(A17,""LOW52""))"),562.9) -> 562.9 | K17: =if(isblank(A17),"",(F17-I17)/I17) -> -0.01041864 | L17: 0 | M17: =IF(ISBLANK(A17), "", IF(AND($N17 >= 0, $N17 <= 75), "||||", IF(AND($N17 > 75, $N17 <= 300), "|||", IF(AND($N17 > 300, $N17 <= 6000), "||", IF($N17 > 6000, "|", ""))))) -> |||| | N17: =IFERROR(__xludf.DUMMYFUNCTION("if(ISBLANK(A17),"""",googlefinance(A17,""Marketcap"")/1000000000)"),60.061319526) -> 60.06132
A18: NSE:AAVAS | B18: =IFERROR(__xludf.DUMMYFUNCTION("if(ISBLANK(A18),"""",GOOGLEFINANCE(A18,""NAME""))"),"Aavas Financiers Ltd") -> Aavas Financiers Ltd | C18: =if(ISBLANK(A18),"",if(K18<-10%,"Buy","Hold")) -> Buy | D18: =if(ISBLANK(A18),"",if(K18<-15%,"Buy","Hold")) -> Buy | E18: =if(ISBLANK(A18),"",if(N18>1401,"Large cap",if(N18>100,"Mid cap","Small cap"))) -> Mid cap | F18: =IFERROR(__xludf.DUMMYFUNCTION("if(ISBLANK(A18),"""",GOOGLEFINANCE(A18,""price""))"),1505.0) -> 1505 | G18: =if(ISBLANK(A18),"",if(L18=0,"Buy@CMP",if(F18<L18,"Buy","Hold"))) -> Buy@CMP | H18: =IFERROR(__xludf.DUMMYFUNCTION("if(ISBLANK(A18),"""",GOOGLEFINANCE(A18,""CHANGEPCT"")/100)"),-0.0059) -> -0.0059 | I18: =IFERROR(__xludf.DUMMYFUNCTION("if(ISBLANK(A18),"""",GOOGLEFINANCE(A18,""HIGH52""))"),2049.0) -> 2049 | J18: =IFERROR(__xludf.DUMMYFUNCTION("if(ISBLANK(A18),"""",GOOGLEFINANCE(A18,""LOW52""))"),1060.4) -> 1060.4 | K18: =if(isblank(A18),"",(F18-I18)/I18) -> -0.26549536 | L18: 0 | M18: =IF(ISBLANK(A18), "", IF(AND($N18 >= 0, $N18 <= 75), "||||", IF(AND($N18 > 75, $N18 <= 300), "|||", IF(AND($N18 > 300, $N18 <= 6000), "||", IF($N18 > 6000, "|", ""))))) -> ||| | N18: =IFERROR(__xludf.DUMMYFUNCTION("if(ISBLANK(A18),"""",googlefinance(A18,""Marketcap"")/1000000000)"),119.761242045) -> 119.76124
A19: NSE:ATUL | B19: =IFERROR(__xludf.DUMMYFUNCTION("if(ISBLANK(A19),"""",GOOGLEFINANCE(A19,""NAME""))"),"Atul Ltd") -> Atul Ltd | C19: =if(ISBLANK(A19),"",if(K19<-10%,"Buy","Hold")) -> Buy | D19: =if(ISBLANK(A19),"",if(K19<-15%,"Buy","Hold")) -> Buy | E19: =if(ISBLANK(A19),"",if(N19>1401,"Large cap",if(N19>100,"Mid cap","Small cap"))) -> Mid cap | F19: =IFERROR(__xludf.DUMMYFUNCTION("if(ISBLANK(A19),"""",GOOGLEFINANCE(A19,""price""))"),6430.0) -> 6430 | G19: =if(ISBLANK(A19),"",if(L19=0,"Buy@CMP",if(F19<L19,"Buy","Hold"))) -> Buy@CMP | H19: =IFERROR(__xludf.DUMMYFUNCTION("if(ISBLANK(A19),"""",GOOGLEFINANCE(A19,""CHANGEPCT"")/100)"),-0.0046) -> -0.0046 | I19: =IFERROR(__xludf.DUMMYFUNCTION("if(ISBLANK(A19),"""",GOOGLEFINANCE(A19,""HIGH52""))"),7788.0) -> 7788 | J19: =IFERROR(__xludf.DUMMYFUNCTION("if(ISBLANK(A19),"""",GOOGLEFINANCE(A19,""LOW52""))"),5560.5) -> 5560.5 | K19: =if(isblank(A19),"",(F19-I19)/I19) -> -0.17437083 | L19: 0 | M19: =IF(ISBLANK(A19), "", IF(AND($N19 >= 0, $N19 <= 75), "||||", IF(AND($N19 > 75, $N19 <= 300), "|||", IF(AND($N19 > 300, $N19 <= 6000), "||", IF($N19 > 6000, "|", ""))))) -> ||| | N19: =IFERROR(__xludf.DUMMYFUNCTION("if(ISBLANK(A19),"""",googlefinance(A19,""Marketcap"")/1000000000)"),189.3105168) -> 189.31052
A20: NSE:AWL | B20: =IFERROR(__xludf.DUMMYFUNCTION("if(ISBLANK(A20),"""",GOOGLEFINANCE(A20,""NAME""))"),"AWL Agri Business Ltd") -> AWL Agri Business Ltd | C20: =if(ISBLANK(A20),"",if(K20<-10%,"Buy","Hold")) -> Buy | D20: =if(ISBLANK(A20),"",if(K20<-15%,"Buy","Hold")) -> Buy | E20: =if(ISBLANK(A20),"",if(N20>1401,"Large cap",if(N20>100,"Mid cap","Small cap"))) -> Mid cap | F20: =IFERROR(__xludf.DUMMYFUNCTION("if(ISBLANK(A20),"""",GOOGLEFINANCE(A20,""price""))"),185.98) -> 185.98 | G20: =if(ISBLANK(A20),"",if(L20=0,"Buy@CMP",if(F20<L20,"Buy","Hold"))) -> Buy@CMP | H20: =IFERROR(__xludf.DUMMYFUNCTION("if(ISBLANK(A20),"""",GOOGLEFINANCE(A20,""CHANGEPCT"")/100)"),-0.025099999999999997) -> -0.0251 | I20: =IFERROR(__xludf.DUMMYFUNCTION("if(ISBLANK(A20),"""",GOOGLEFINANCE(A20,""HIGH52""))"),286.0) -> 286 | J20: =IFERROR(__xludf.DUMMYFUNCTION("if(ISBLANK(A20),"""",GOOGLEFINANCE(A20,""LOW52""))"),171.19) -> 171.19 | K20: =if(isblank(A20),"",(F20-I20)/I20) -> -0.34972028 | L20: 0 | M20: =IF(ISBLANK(A20), "", IF(AND($N20 >= 0, $N20 <= 75), "||||", IF(AND($N20 > 75, $N20 <= 300), "|||", IF(AND($N20 > 300, $N20 <= 6000), "||", IF($N20 > 6000, "|", ""))))) -> ||| | N20: =IFERROR(__xludf.DUMMYFUNCTION("if(ISBLANK(A20),"""",googlefinance(A20,""Marketcap"")/1000000000)"),240.421754645) -> 240.42175
A21: NSE:BRITANNIA | B21: =IFERROR(__xludf.DUMMYFUNCTION("if(ISBLANK(A21),"""",GOOGLEFINANCE(A21,""NAME""))"),"Britannia Industries Ltd") -> Britannia Industries Ltd | C21: =if(ISBLANK(A21),"",if(K21<-10%,"Buy","Hold")) -> Buy | D21: =if(ISBLANK(A21),"",if(K21<-15%,"Buy","Hold")) -> Hold | E21: =if(ISBLANK(A21),"",if(N21>1401,"Large cap",if(N21>100,"Mid cap","Small cap"))) -> Mid cap | F21: =IFERROR(__xludf.DUMMYFUNCTION("if(ISBLANK(A21),"""",GOOGLEFINANCE(A21,""price""))"),5452.0) -> 5452 | G21: =if(ISBLANK(A21),"",if(L21=0,"Buy@CMP",if(F21<L21,"Buy","Hold"))) -> Buy@CMP | H21: =IFERROR(__xludf.DUMMYFUNCTION("if(ISBLANK(A21),"""",GOOGLEFINANCE(A21,""CHANGEPCT"")/100)"),-5.0E-4) -> -0.0005 | I21: =IFERROR(__xludf.DUMMYFUNCTION("if(ISBLANK(A21),"""",GOOGLEFINANCE(A21,""HIGH52""))"),6336.0) -> 6336 | J21: =IFERROR(__xludf.DUMMYFUNCTION("if(ISBLANK(A21),"""",GOOGLEFINANCE(A21,""LOW52""))"),5035.0) -> 5035 | K21: =if(isblank(A21),"",(F21-I21)/I21) -> -0.1395202 | L21: 0 | M21: =IF(ISBLANK(A21), "", IF(AND($N21 >= 0, $N21 <= 75), "||||", IF(AND($N21 > 75, $N21 <= 300), "|||", IF(AND($N21 > 300, $N21 <= 6000), "||", IF($N21 > 6000, "|", ""))))) -> || | N21: =IFERROR(__xludf.DUMMYFUNCTION("if(ISBLANK(A21),"""",googlefinance(A21,""Marketcap"")/1000000000)"),1313.2139716) -> 1313.214
A22: NSE:CHAMBLFERT | B22: =IFERROR(__xludf.DUMMYFUNCTION("if(ISBLANK(A22),"""",GOOGLEFINANCE(A22,""NAME""))"),"Chambal Fertilisers and Chemicals Ltd") -> Chambal Fertilisers and Chemicals Ltd | C22: =if(ISBLANK(A22),"",if(K22<-10%,"Buy","Hold")) -> Buy | D22: =if(ISBLANK(A22),"",if(K22<-15%,"Buy","Hold")) -> Buy | E22: =if(ISBLANK(A22),"",if(N22>1401,"Large cap",if(N22>100,"Mid cap","Small cap"))) -> Mid cap | F22: =IFERROR(__xludf.DUMMYFUNCTION("if(ISBLANK(A22),"""",GOOGLEFINANCE(A22,""price""))"),464.45) -> 464.45 | G22: =if(ISBLANK(A22),"",if(L22=0,"Buy@CMP",if(F22<L22,"Buy","Hold"))) -> Buy@CMP | H22: =IFERROR(__xludf.DUMMYFUNCTION("if(ISBLANK(A22),"""",GOOGLEFINANCE(A22,""CHANGEPCT"")/100)"),-0.024399999999999998) -> -0.0244 | I22: =IFERROR(__xludf.DUMMYFUNCTION("if(ISBLANK(A22),"""",GOOGLEFINANCE(A22,""HIGH52""))"),580.7) -> 580.7 | J22: =IFERROR(__xludf.DUMMYFUNCTION("if(ISBLANK(A22),"""",GOOGLEFINANCE(A22,""LOW52""))"),399.75) -> 399.75 | K22: =if(isblank(A22),"",(F22-I22)/I22) -> -0.20018943 | L22: 0 | M22: =IF(ISBLANK(A22), "", IF(AND($N22 >= 0, $N22 <= 75), "||||", IF(AND($N22 > 75, $N22 <= 300), "|||", IF(AND($N22 > 300, $N22 <= 6000), "||", IF($N22 > 6000, "|", ""))))) -> ||| | N22: =IFERROR(__xludf.DUMMYFUNCTION("if(ISBLANK(A22),"""",googlefinance(A22,""Marketcap"")/1000000000)"),186.08291918) -> 186.08292
A23: NSE:CUMMINSIND | B23: =IFERROR(__xludf.DUMMYFUNCTION("if(ISBLANK(A23),"""",GOOGLEFINANCE(A23,""NAME""))"),"Cummins India Ltd") -> Cummins India Ltd | C23: =if(ISBLANK(A23),"",if(K23<-10%,"Buy","Hold")) -> Buy | D23: =if(ISBLANK(A23),"",if(K23<-15%,"Buy","Hold")) -> Hold | E23: =if(ISBLANK(A23),"",if(N23>1401,"Large cap",if(N23>100,"Mid cap","Small cap"))) -> Large cap | F23: =IFERROR(__xludf.DUMMYFUNCTION("if(ISBLANK(A23),"""",GOOGLEFINANCE(A23,""price""))"),5465.0) -> 5465 | G23: =if(ISBLANK(A23),"",if(L23=0,"Buy@CMP",if(F23<L23,"Buy","Hold"))) -> Buy@CMP | H23: =IFERROR(__xludf.DUMMYFUNCTION("if(ISBLANK(A23),"""",GOOGLEFINANCE(A23,""CHANGEPCT"")/100)"),-0.0203) -> -0.0203 | I23: =IFERROR(__xludf.DUMMYFUNCTION("if(ISBLANK(A23),"""",GOOGLEFINANCE(A23,""HIGH52""))"),6100.0) -> 6100 | J23: =IFERROR(__xludf.DUMMYFUNCTION("if(ISBLANK(A23),"""",GOOGLEFINANCE(A23,""LOW52""))"),3330.3) -> 3330.3 | K23: =if(isblank(A23),"",(F23-I23)/I23) -> -0.10409836 | L23: 0 | M23: =IF(ISBLANK(A23), "", IF(AND($N23 >= 0, $N23 <= 75), "||||", IF(AND($N23 > 75, $N23 <= 300), "|||", IF(AND($N23 > 300, $N23 <= 6000), "||", IF($N23 > 6000, "|", ""))))) -> || | N23: =IFERROR(__xludf.DUMMYFUNCTION("if(ISBLANK(A23),"""",googlefinance(A23,""Marketcap"")/1000000000)"),1514.898) -> 1514.898
A24: NSE:DCMNVL | B24: =IFERROR(__xludf.DUMMYFUNCTION("if(ISBLANK(A24),"""",GOOGLEFINANCE(A24,""NAME""))"),"DCM Nouvelle Ltd") -> DCM Nouvelle Ltd | C24: =if(ISBLANK(A24),"",if(K24<-10%,"Buy","Hold")) -> Buy | D24: =if(ISBLANK(A24),"",if(K24<-15%,"Buy","Hold")) -> Buy | E24: =if(ISBLANK(A24),"",if(N24>1401,"Large cap",if(N24>100,"Mid cap","Small cap"))) -> Small cap | F24: =IFERROR(__xludf.DUMMYFUNCTION("if(ISBLANK(A24),"""",GOOGLEFINANCE(A24,""price""))"),148.2) -> 148.2 | G24: =if(ISBLANK(A24),"",if(L24=0,"Buy@CMP",if(F24<L24,"Buy","Hold"))) -> Buy@CMP | H24: =IFERROR(__xludf.DUMMYFUNCTION("if(ISBLANK(A24),"""",GOOGLEFINANCE(A24,""CHANGEPCT"")/100)"),-0.0342) -> -0.0342 | I24: =IFERROR(__xludf.DUMMYFUNCTION("if(ISBLANK(A24),"""",GOOGLEFINANCE(A24,""HIGH52""))"),203.8) -> 203.8 | J24: =IFERROR(__xludf.DUMMYFUNCTION("if(ISBLANK(A24),"""",GOOGLEFINANCE(A24,""LOW52""))"),95.6) -> 95.6 | K24: =if(isblank(A24),"",(F24-I24)/I24) -> -0.27281649 | L24: 0 | M24: =IF(ISBLANK(A24), "", IF(AND($N24 >= 0, $N24 <= 75), "||||", IF(AND($N24 > 75, $N24 <= 300), "|||", IF(AND($N24 > 300, $N24 <= 6000), "||", IF($N24 > 6000, "|", ""))))) -> |||| | N24: =IFERROR(__xludf.DUMMYFUNCTION("if(ISBLANK(A24),"""",googlefinance(A24,""Marketcap"")/1000000000)"),2.739835945) -> 2.7398359
A25: NSE:DIVISLAB | B25: =IFERROR(__xludf.DUMMYFUNCTION("if(ISBLANK(A25),"""",GOOGLEFINANCE(A25,""NAME""))"),"Divi's Laboratories Ltd") -> Divi's Laboratories Ltd | C25: =if(ISBLANK(A25),"",if(K25<-10%,"Buy","Hold")) -> Hold | D25: =if(ISBLANK(A25),"",if(K25<-15%,"Buy","Hold")) -> Hold | E25: =if(ISBLANK(A25),"",if(N25>1401,"Large cap",if(N25>100,"Mid cap","Small cap"))) -> Large cap | F25: =IFERROR(__xludf.DUMMYFUNCTION("if(ISBLANK(A25),"""",GOOGLEFINANCE(A25,""price""))"),6760.0) -> 6760 | G25: =if(ISBLANK(A25),"",if(L25=0,"Buy@CMP",if(F25<L25,"Buy","Hold"))) -> Buy@CMP | H25: =IFERROR(__xludf.DUMMYFUNCTION("if(ISBLANK(A25),"""",GOOGLEFINANCE(A25,""CHANGEPCT"")/100)"),-0.014199999999999999) -> -0.0142 | I25: =IFERROR(__xludf.DUMMYFUNCTION("if(ISBLANK(A25),"""",GOOGLEFINANCE(A25,""HIGH52""))"),7071.5) -> 7071.5 | J25: =IFERROR(__xludf.DUMMYFUNCTION("if(ISBLANK(A25),"""",GOOGLEFINANCE(A25,""LOW52""))"),5636.5) -> 5636.5 | K25: =if(isblank(A25),"",(F25-I25)/I25) -> -0.04405006 | L25: 0 | M25: =IF(ISBLANK(A25), "", IF(AND($N25 >= 0, $N25 <= 75), "||||", IF(AND($N25 > 75, $N25 <= 300), "|||", IF(AND($N25 > 300, $N25 <= 6000), "||", IF($N25 > 6000, "|", ""))))) -> || | N25: =IFERROR(__xludf.DUMMYFUNCTION("if(ISBLANK(A25),"""",googlefinance(A25,""Marketcap"")/1000000000)"),1803.676043028) -> 1803.676
A26: NSE:ETHOSLTD | B26: =IFERROR(__xludf.DUMMYFUNCTION("if(ISBLANK(A26),"""",GOOGLEFINANCE(A26,""NAME""))"),"Ethos Ltd") -> Ethos Ltd | C26: =if(ISBLANK(A26),"",if(K26<-10%,"Buy","Hold")) -> Buy | D26: =if(ISBLANK(A26),"",if(K26<-15%,"Buy","Hold")) -> Buy | E26: =if(ISBLANK(A26),"",if(N26>1401,"Large cap",if(N26>100,"Mid cap","Small cap"))) -> Small cap | F26: =IFERROR(__xludf.DUMMYFUNCTION("if(ISBLANK(A26),"""",GOOGLEFINANCE(A26,""price""))"),2503.2) -> 2503.2 | G26: =if(ISBLANK(A26),"",if(L26=0,"Buy@CMP",if(F26<L26,"Buy","Hold"))) -> Buy@CMP | H26: =IFERROR(__xludf.DUMMYFUNCTION("if(ISBLANK(A26),"""",GOOGLEFINANCE(A26,""CHANGEPCT"")/100)"),-0.0134) -> -0.0134 | I26: =IFERROR(__xludf.DUMMYFUNCTION("if(ISBLANK(A26),"""",GOOGLEFINANCE(A26,""HIGH52""))"),3245.9) -> 3245.9 | J26: =IFERROR(__xludf.DUMMYFUNCTION("if(ISBLANK(A26),"""",GOOGLEFINANCE(A26,""LOW52""))"),1919.4) -> 1919.4 | K26: =if(isblank(A26),"",(F26-I26)/I26) -> -0.22881173 | L26: 0 | M26: =IF(ISBLANK(A26), "", IF(AND($N26 >= 0, $N26 <= 75), "||||", IF(AND($N26 > 75, $N26 <= 300), "|||", IF(AND($N26 > 300, $N26 <= 6000), "||", IF($N26 > 6000, "|", ""))))) -> |||| | N26: =IFERROR(__xludf.DUMMYFUNCTION("if(ISBLANK(A26),"""",googlefinance(A26,""Marketcap"")/1000000000)"),66.979848301) -> 66.979848
A27: NSE:GILLETTE | B27: =IFERROR(__xludf.DUMMYFUNCTION("if(ISBLANK(A27),"""",GOOGLEFINANCE(A27,""NAME""))"),"Gillette India Ltd") -> Gillette India Ltd | C27: =if(ISBLANK(A27),"",if(K27<-10%,"Buy","Hold")) -> Buy | D27: =if(ISBLANK(A27),"",if(K27<-15%,"Buy","Hold")) -> Buy | E27: =if(ISBLANK(A27),"",if(N27>1401,"Large cap",if(N27>100,"Mid cap","Small cap"))) -> Mid cap | F27: =IFERROR(__xludf.DUMMYFUNCTION("if(ISBLANK(A27),"""",GOOGLEFINANCE(A27,""price""))"),7862.0) -> 7862 | G27: =if(ISBLANK(A27),"",if(L27=0,"Buy@CMP",if(F27<L27,"Buy","Hold"))) -> Buy@CMP | H27: =IFERROR(__xludf.DUMMYFUNCTION("if(ISBLANK(A27),"""",GOOGLEFINANCE(A27,""CHANGEPCT"")/100)"),0.0115) -> 0.0115 | I27: =IFERROR(__xludf.DUMMYFUNCTION("if(ISBLANK(A27),"""",GOOGLEFINANCE(A27,""HIGH52""))"),11500.0) -> 11500 | J27: =IFERROR(__xludf.DUMMYFUNCTION("if(ISBLANK(A27),"""",GOOGLEFINANCE(A27,""LOW52""))"),7206.0) -> 7206 | K27: =if(isblank(A27),"",(F27-I27)/I27) -> -0.31634783 | L27: 0 | M27: =IF(ISBLANK(A27), "", IF(AND($N27 >= 0, $N27 <= 75), "||||", IF(AND($N27 > 75, $N27 <= 300), "|||", IF(AND($N27 > 300, $N27 <= 6000), "||", IF($N27 > 6000, "|", ""))))) -> ||| | N27: =IFERROR(__xludf.DUMMYFUNCTION("if(ISBLANK(A27),"""",googlefinance(A27,""Marketcap"")/1000000000)"),256.18492102) -> 256.18492
A28: NSE:HAL | B28: =IFERROR(__xludf.DUMMYFUNCTION("if(ISBLANK(A28),"""",GOOGLEFINANCE(A28,""NAME""))"),"Hindustan Aeronautics Ltd") -> Hindustan Aeronautics Ltd | C28: =if(ISBLANK(A28),"",if(K28<-10%,"Buy","Hold")) -> Buy | D28: =if(ISBLANK(A28),"",if(K28<-15%,"Buy","Hold")) -> Hold | E28: =if(ISBLANK(A28),"",if(N28>1401,"Large cap",if(N28>100,"Mid cap","Small cap"))) -> Large cap | F28: =IFERROR(__xludf.DUMMYFUNCTION("if(ISBLANK(A28),"""",GOOGLEFINANCE(A28,""price""))"),4401.0) -> 4401 | G28: =if(ISBLANK(A28),"",if(L28=0,"Buy@CMP",if(F28<L28,"Buy","Hold"))) -> Buy@CMP | H28: =IFERROR(__xludf.DUMMYFUNCTION("if(ISBLANK(A28),"""",GOOGLEFINANCE(A28,""CHANGEPCT"")/100)"),-0.0089) -> -0.0089 | I28: =IFERROR(__xludf.DUMMYFUNCTION("if(ISBLANK(A28),"""",GOOGLEFINANCE(A28,""HIGH52""))"),5065.0) -> 5065 | J28: =IFERROR(__xludf.DUMMYFUNCTION("if(ISBLANK(A28),"""",GOOGLEFINANCE(A28,""LOW52""))"),3479.1) -> 3479.1 | K28: =if(isblank(A28),"",(F28-I28)/I28) -> -0.13109576 | L28: 0 | M28: =IF(ISBLANK(A28), "", IF(AND($N28 >= 0, $N28 <= 75), "||||", IF(AND($N28 > 75, $N28 <= 300), "|||", IF(AND($N28 > 300, $N28 <= 6000), "||", IF($N28 > 6000, "|", ""))))) -> || | N28: =IFERROR(__xludf.DUMMYFUNCTION("if(ISBLANK(A28),"""",googlefinance(A28,""Marketcap"")/1000000000)"),2942.895888) -> 2942.8959
